Workbook

Sheet Livro Diario - FC
E1: 0
C3: Livro Diário - Lançamento das Contas
AA4: ocultar
C9: =TODAY() -> 46144 | AE9: Plano Contas | AH9: Contas
C10: Status | D10: Data | E10: Contas | F10: Volume da Embalagem | G10: Und. Medida | H10: Cliente / Fornecedor | I10: Histórico | J10: A Receber | K10: A Pagar | L10: Entrada | M10: Saída | N10: Orig/Dest | P10: Falta Receber | Q10: Falta Pagar | AA10: A pagar | AB10: A receber
D11: 46027 | E11: 3.1.1 Receita com Cash - Diaria | F11: . | G11: . | H11: Vendas Diarias | I11: Deposito Dinheiro | J11: 260 | L11: 260 | N11: DINHEIRO | O11: =IF(K11=0,"",IF(AND(K11>0,K11>M11),K11-M11,"")) | P11: =IF(J11="","",J11-L11) -> 0 | Q11: =IF(K11="","",K11-M11) | AA11: =IF(K11=0,"",IF(AND(K11>0,K11>M11),K11-M11,"")) | AB11: =IF(J11=0,"",IF(AND(J11>0,J11>L11),J11-L11,"")) | AE11: 3.1 Receita de Vendas | AH11: DINHEIRO
D12: 46027 | E12: 3.1.2 Receita com Cartão (Caixa) | F12: . | G12: . | H12: Vendas Cartão | I12: Recebiveis Cartão | N12: CAIXA ECONOMICA | P12: =IF(J12="","",J12-L12) | Q12: =IF(K12="","",K12-M12) | AA12: =IF(K12=0,"",IF(AND(K12>0,K12>M12),K12-M12,"")) | AB12: =IF(J12=0,"",IF(AND(J12>0,J12>L12),J12-L12,"")) | AE12: 3.1.1 Receita com Cash - Diaria | AH12: Fundo de Investimento - Ifood
D13: 46027 | E13: 3.1.3 Receita Ifood | F13: . | G13: . | H13: Vendas Ifood | I13: Recebimento Ifood | N13: IFOOD | P13: =IF(J13="","",J13-L13) | Q13: =IF(K13="","",K13-M13) | AA13: =IF(K13=0,"",IF(AND(K13>0,K13>M13),K13-M13,"")) | AB13: =IF(J13=0,"",IF(AND(J13>0,J13>L13),J13-L13,"")) | AE13: 3.1.2 Receita com Cartão (Caixa) | AH13: Capital de Giro - Caixa Economica
D14: 46027 | E14: 3.1.4 Receita com Cartão - (Infinity Emp) | F14: . | G14: . | H14: Vendas na Infinity | I14: Recebiveis Cartão/Pix | N14: INFINITY EMPORIO | P14: =IF(J14="","",J14-L14) | Q14: =IF(K14="","",K14-M14) | AA14: =IF(K14=0,"",IF(AND(K14>0,K14>M14),K14-M14,"")) | AB14: =IF(J14=0,"",IF(AND(J14>0,J14>L14),J14-L14,"")) | AE14: 3.1.3 Receita Ifood | AH14: Fundo de Reserva - Cash
D15: 46027 | E15: 3.1.5 Receita com Cartão - (Infinity Sil) | F15: . | G15: . | H15: Vendas na Infinity | I15: Recebiveis Cartão/Pix | N15: INFINITY SILVIO | P15: =IF(J15="","",J15-L15) | Q15: =IF(K15="","",K15-M15) | AA15: =IF(K15=0,"",IF(AND(K15>0,K15>M15),K15-M15,"")) | AB15: =IF(J15=0,"",IF(AND(J15>0,J15>L15),J15-L15,"")) | AE15: 3.1.4 Receita com Cartão - (Infinity Emp) | AH15: CAIXA ECONOMICA
D16: 46027 | E16: Toscana Frango | F16: 3,030 | G16: kg | H16: Só Frios | I16: Proteina | K16: 69.66 | M16: 69.66 | P16: =IF(J16="","",J16-L16) | Q16: =IF(K16="","",K16-M16) -> 0 | AA16: =IF(K16=0,"",IF(AND(K16>0,K16>M16),K16-M16,"")) | AB16: =IF(J16=0,"",IF(AND(J16>0,J16>L16),J16-L16,"")) | AE16: 3.1.5 Receita com Cartão - (Infinity Sil) | AH16: INFINITY EMPORIO
D17: 46027 | E17: Coxão Mole (Bife) | F17: 2,816 | G17: kg | H17: Só Frios | I17: Proteina | K17: 87.27 | M17: 87.27 | P17: =IF(J17="","",J17-L17) | Q17: =IF(K17="","",K17-M17) -> 0 | AA17: =IF(K17=0,"",IF(AND(K17>0,K17>M17),K17-M17,"")) | AB17: =IF(J17=0,"",IF(AND(J17>0,J17>L17),J17-L17,"")) | AE17: 3.1.6 - | AH17: IFOOD
D18: 46027 | E18: Carne para Guisada (picadão) | F18: 2,686 | G18: kg | H18: Só Frios | I18: Proteina | K18: 77.87 | M18: 77.87 | P18: =IF(J18="","",J18-L18) | Q18: =IF(K18="","",K18-M18) -> 0 | AA18: =IF(K18=0,"",IF(AND(K18>0,K18>M18),K18-M18,"")) | AB18: =IF(J18=0,"",IF(AND(J18>0,J18>L18),J18-L18,"")) | AE18: 3.1.7 - | AH18: INFINITY SILVIO
D19: 46027 | E19: Figado Bovino | F19: 0,992 | G19: kg | H19: Só Frios | I19: Proteina | K19: 15.86 | M19: 15.86 | P19: =IF(J19="","",J19-L19) | Q19: =IF(K19="","",K19-M19) -> 0 | AA19: =IF(K19=0,"",IF(AND(K19>0,K19>M19),K19-M19,"")) | AB19: =IF(J19=0,"",IF(AND(J19>0,J19>L19),J19-L19,"")) | AE19: 3.1.8 - | AH19: -
D20: 46027 | E20: Compras Diversos | F20: . | G20: . | H20: Só Frios | I20: Abacate | K20: 11.29 | M20: 11.29 | P20: =IF(J20="","",J20-L20) | Q20: =IF(K20="","",K20-M20) -> 0 | AA20: =IF(K20=0,"",IF(AND(K20>0,K20>M20),K20-M20,"")) | AB20: =IF(J20=0,"",IF(AND(J20>0,J20>L20),J20-L20,"")) | AE20: 3.1.9 .
D21: 46027 | E21: Compras Diversos | F21: . | G21: . | H21: Só Frios | I21: Maça | K21: 6.16 | M21: 6.16 | P21: =IF(J21="","",J21-L21) | Q21: =IF(K21="","",K21-M21) -> 0 | AA21: =IF(K21=0,"",IF(AND(K21>0,K21>M21),K21-M21,"")) | AB21: =IF(J21=0,"",IF(AND(J21>0,J21>L21),J21-L21,"")) | AE21: 3.1.10 Acerto
D22: 46026 | E22: Tomate | F22: 23,000 | G22: kg | H22: Ceasa | I22: Verduras | K22: 40 | M22: 40 | N22: DINHEIRO | P22: =IF(J22="","",J22-L22) | Q22: =IF(K22="","",K22-M22) -> 0 | AA22: =IF(K22=0,"",IF(AND(K22>0,K22>M22),K22-M22,"")) | AB22: =IF(J22=0,"",IF(AND(J22>0,J22>L22),J22-L22,"")) | AE22: 3.1.11 -
D23: 46026 | E23: Cebola | F23: 20,000 | G23: kg | H23: Ceasa | I23: Verduras | K23: 50 | M23: 50 | N23: DINHEIRO | P23: =IF(J23="","",J23-L23) | Q23: =IF(K23="","",K23-M23) -> 0 | AA23: =IF(K23=0,"",IF(AND(K23>0,K23>M23),K23-M23,"")) | AB23: =IF(J23=0,"",IF(AND(J23>0,J23>L23),J23-L23,"")) | AE23: 3.1.12 -
D24: 46026 | E24: Batata Inglesa | F24: 25,000 | G24: kg | H24: Ceasa | I24: Verduras | K24: 80 | M24: 80 | N24: DINHEIRO | P24: =IF(J24="","",J24-L24) | Q24: =IF(K24="","",K24-M24) -> 0 | AA24: =IF(K24=0,"",IF(AND(K24>0,K24>M24),K24-M24,"")) | AB24: =IF(J24=0,"",IF(AND(J24>0,J24>L24),J24-L24,"")) | AE24: 3.1.13 -
D25: 46026 | E25: Pimenta Cheiro | F25: 1,000 | G25: kg | H25: Ceasa | I25: Temperos | P25: =IF(J25="","",J25-L25) | Q25: =IF(K25="","",K25-M25) | AA25: =IF(K25=0,"",IF(AND(K25>0,K25>M25),K25-M25,"")) | AB25: =IF(J25=0,"",IF(AND(J25>0,J25>L25),J25-L25,"")) | AE25: 3.1.14 -
D26: 46026 | E26: Cenoura | F26: 10,000 | G26: kg | H26: Ceasa | I26: Verduras | P26: =IF(J26="","",J26-L26) | Q26: =IF(K26="","",K26-M26) | AA26: =IF(K26=0,"",IF(AND(K26>0,K26>M26),K26-M26,"")) | AB26: =IF(J26=0,"",IF(AND(J26>0,J26>L26),J26-L26,"")) | AE26: 3.1.15 -
D27: 46026 | E27: Chuchu | F27: 12,000 | G27: kg | H27: Ceasa | I27: Verduras | P27: =IF(J27="","",J27-L27) | Q27: =IF(K27="","",K27-M27) | AA27: =IF(K27=0,"",IF(AND(K27>0,K27>M27),K27-M27,"")) | AB27: =IF(J27=0,"",IF(AND(J27>0,J27>L27),J27-L27,"")) | AE27: DESPESAS/CUSTOS VARIÁVEIS
D28: 46026 | E28: Abobora | F28: 7,000 | G28: kg | H28: Ceasa | I28: Verduras | K28: 22 | M28: 22 | N28: DINHEIRO | P28: =IF(J28="","",J28-L28) | Q28: =IF(K28="","",K28-M28) -> 0 | AA28: =IF(K28=0,"",IF(AND(K28>0,K28>M28),K28-M28,"")) | AB28: =IF(J28=0,"",IF(AND(J28>0,J28>L28),J28-L28,"")) | AE28: 4.1 Custos Tributários e Financeiros
D29: 46026 | E29: Coentro | F29: 6,000 | G29: kg | H29: Ceasa | I29: Temperos | K29: 20 | M29: 20 | N29: DINHEIRO | P29: =IF(J29="","",J29-L29) | Q29: =IF(K29="","",K29-M29) -> 0 | AA29: =IF(K29=0,"",IF(AND(K29>0,K29>M29),K29-M29,"")) | AB29: =IF(J29=0,"",IF(AND(J29>0,J29>L29),J29-L29,"")) | AE29: 4.1.1 Simples Federal
D30: 46026 | E30: Limão | F30: 100 | G30: und | H30: Ceasa | I30: Frutas | P30: =IF(J30="","",J30-L30) | Q30: =IF(K30="","",K30-M30) | AA30: =IF(K30=0,"",IF(AND(K30>0,K30>M30),K30-M30,"")) | AB30: =IF(J30=0,"",IF(AND(J30>0,J30>L30),J30-L30,"")) | AE30: 4.1.2 Mercantil
D31: 46026 | E31: Laranja | F31: 100 | G31: und | H31: Ceasa | I31: Frutas | K31: 40 | M31: 40 | N31: DINHEIRO | P31: =IF(J31="","",J31-L31) | Q31: =IF(K31="","",K31-M31) -> 0 | AA31: =IF(K31=0,"",IF(AND(K31>0,K31>M31),K31-M31,"")) | AB31: =IF(J31=0,"",IF(AND(J31>0,J31>L31),J31-L31,"")) | AE31: 4.1.3 IPTU
D32: 46026 | E32: Pão ou Torrada | F32: 30 | G32: pct | H32: Ceasa | I32: Insumos | K32: 90 | M32: 90 | N32: DINHEIRO | P32: =IF(J32="","",J32-L32) | Q32: =IF(K32="","",K32-M32) -> 0 | AA32: =IF(K32=0,"",IF(AND(K32>0,K32>M32),K32-M32,"")) | AB32: =IF(J32=0,"",IF(AND(J32>0,J32>L32),J32-L32,"")) | AE32: 4.1.4 FGTS
D33: 46026 | E33: Bolo de Noiva | F33: 1,000 | G33: kg | H33: Ceasa | I33: SobreMesas | K33: 35 | M33: 35 | N33: DINHEIRO | P33: =IF(J33="","",J33-L33) | Q33: =IF(K33="","",K33-M33) -> 0 | AA33: =IF(K33=0,"",IF(AND(K33>0,K33>M33),K33-M33,"")) | AB33: =IF(J33=0,"",IF(AND(J33>0,J33>L33),J33-L33,"")) | AE33: 4.1.5 INSS
D34: 46026 | E34: Cocada | F34: 28 | G34: und | H34: Ceasa | I34: SobreMesas | K34: 48 | M34: 48 | N34: DINHEIRO | P34: =IF(J34="","",J34-L34) | Q34: =IF(K34="","",K34-M34) -> 0 | AA34: =IF(K34=0,"",IF(AND(K34>0,K34>M34),K34-M34,"")) | AB34: =IF(J34=0,"",IF(AND(J34>0,J34>L34),J34-L34,"")) | AE34: 4.1.6 Parcelamento Imposto
D35: 46026 | E35: Ovos de Galinha | F35: 30 | G35: und | H35: Ceasa | I35: Proteina | P35: =IF(J35="","",J35-L35) | Q35: =IF(K35="","",K35-M35) | AA35: =IF(K35=0,"",IF(AND(K35>0,K35>M35),K35-M35,"")) | AB35: =IF(J35=0,"",IF(AND(J35>0,J35>L35),J35-L35,"")) | AE35: 4.1.7 Parcelamento Imposto
D36: 46026 | E36: Macaxeira | F36: 25 | G36: kg | H36: Ceasa | I36: Raiz | K36: 75 | M36: 75 | N36: DINHEIRO | P36: =IF(J36="","",J36-L36) | Q36: =IF(K36="","",K36-M36) -> 0 | AA36: =IF(K36=0,"",IF(AND(K36>0,K36>M36),K36-M36,"")) | AB36: =IF(J36=0,"",IF(AND(J36>0,J36>L36),J36-L36,"")) | AE36: 4.1.8 .
D37: 46026 | E37: Inhame | F37: 15 | G37: kg | H37: Ceasa | I37: Raiz | K37: 50 | M37: 50 | N37: DINHEIRO | P37: =IF(J37="","",J37-L37) | Q37: =IF(K37="","",K37-M37) -> 0 | AA37: =IF(K37=0,"",IF(AND(K37>0,K37>M37),K37-M37,"")) | AB37: =IF(J37=0,"",IF(AND(J37>0,J37>L37),J37-L37,"")) | AE37: 4.1.9 .
D38: 46026 | E38: Bucha de Prato | F38: 20 | G38: und | H38: Assaí | I38: Limpeza | K38: R$ 31,00 | M38: R$ 31,00 | N38: CAIXA ECONOMICA | P38: =IF(J38="","",J38-L38) | Q38: =IF(K38="","",K38-M38) -> #VALUE! | AA38: =IF(K38=0,"",IF(AND(K38>0,K38>M38),K38-M38,"")) | AB38: =IF(J38=0,"",IF(AND(J38>0,J38>L38),J38-L38,"")) | AE38: CUSTOS COM PRODUTOS
D39: 46026 | E39: Desinfetante | F39: 1 | G39: und | H39: Assaí | I39: Limpeza | K39: R$ 6,89 | M39: R$ 6,89 | N39: CAIXA ECONOMICA | P39: =IF(J39="","",J39-L39) | Q39: =IF(K39="","",K39-M39) -> #VALUE! | AA39: =IF(K39=0,"",IF(AND(K39>0,K39>M39),K39-M39,"")) | AB39: =IF(J39=0,"",IF(AND(J39>0,J39>L39),J39-L39,"")) | AE39: INSUMOS
D40: 46026 | E40: Desinfetante | F40: 2 | G40: und | H40: Assaí | I40: Limpeza | K40: R$ 11,38 | M40: R$ 11,38 | N40: CAIXA ECONOMICA | P40: =IF(J40="","",J40-L40) | Q40: =IF(K40="","",K40-M40) -> #VALUE! | AA40: =IF(K40=0,"",IF(AND(K40>0,K40>M40),K40-M40,"")) | AB40: =IF(J40=0,"",IF(AND(J40>0,J40>L40),J40-L40,"")) | AE40: Macarrão
D41: 46026 | E41: Bucha de Prato | F41: 1 | G41: und | H41: Assaí | I41: Limpeza | K41: R$ 4,60 | M41: R$ 4,60 | N41: CAIXA ECONOMICA | P41: =IF(J41="","",J41-L41) | Q41: =IF(K41="","",K41-M41) -> #VALUE! | AA41: =IF(K41=0,"",IF(AND(K41>0,K41>M41),K41-M41,"")) | AB41: =IF(J41=0,"",IF(AND(J41>0,J41>L41),J41-L41,"")) | AE41: Arroz
D42: 46026 | E42: Sabão em Pó | F42: 1 | G42: und | H42: Assaí | I42: Limpeza | K42: 7.29 | M42: 7.29 | N42: CAIXA ECONOMICA | P42: =IF(J42="","",J42-L42) | Q42: =IF(K42="","",K42-M42) -> 0 | AA42: =IF(K42=0,"",IF(AND(K42>0,K42>M42),K42-M42,"")) | AB42: =IF(J42=0,"",IF(AND(J42>0,J42>L42),J42-L42,"")) | AE42: Feijão mulato
D43: 46026 | E43: Pastilha Banheiro | F43: 1 | G43: und | H43: Assaí | I43: Limpeza | K43: 7.29 | M43: 7.29 | N43: CAIXA ECONOMICA | P43: =IF(J43="","",J43-L43) -> #VALUE! | Q43: =IF(K43="","",K43-M43) -> 0 | AA43: =IF(K43=0,"",IF(AND(K43>0,K43>M43),K43-M43,"")) | AB43: =IF(J43=0,"",IF(AND(J43>0,J43>L43),J43-L43,"")) -> #VALUE! | AE43: Feijão Preto
D44: 46026 | E44: Papel Higienico | F44: 1 | G44: pct | H44: Assaí | I44: Limpeza | K44: 12.8 | M44: 12.8 | N44: CAIXA ECONOMICA | P44: =IF(J44="","",J44-L44) | Q44: =IF(K44="","",K44-M44) -> 0 | AA44: =IF(K44=0,"",IF(AND(K44>0,K44>M44),K44-M44,"")) | AB44: =IF(J44=0,"",IF(AND(J44>0,J44>L44),J44-L44,"")) | AE44: Feijão macassar
D45: 46026 | E45: Sabão em Pó | F45: 9 | G45: und | H45: Assaí | I45: Limpeza | K45: 15.99 | M45: 15.99 | N45: CAIXA ECONOMICA | P45: =IF(J45="","",J45-L45) -> #VALUE! | Q45: =IF(K45="","",K45-M45) -> 0 | AA45: =IF(K45=0,"",IF(AND(K45>0,K45>M45),K45-M45,"")) | AB45: =IF(J45=0,"",IF(AND(J45>0,J45>L45),J45-L45,"")) -> #VALUE! | AE45: Sal
...

Sheet Fluxo de Caixa
C2: Meta de Lucro % = 15% | D2: Faturamento | E2: =E11 -> 7753.7 | F2: =IF(E$2=0,"",E2/E$2) -> 1 | I2: Faturamento | J2: =J11 -> 0 | K2: =IF(J$2=0,"",J2/J$2) | N2: Faturamento | O2: =O11 -> 0 | P2: =IF(O$2=0,"",O2/O$2) | S2: Faturamento | T2: =T11 -> 0 | U2: =IF(T$2=0,"",T2/T$2) | X2: Faturamento | Y2: =Y11 -> 0 | Z2: =IF(Y$2=0,"",Y2/Y$2) | AC2: Faturamento | AD2: =AD11 -> 0 | AE2: =IF(AD$2=0,"",AD2/AD$2) | AG2: Faturamento | AH2: =AH11 -> 0 | AI2: =IF(AH$2=0,"",AH2/AH$2) | AK2: Faturamento | AL2: =AL11 -> 0 | AM2: =IF(AL$2=0,"",AL2/AL$2) | AO2: Faturamento | AP2: =AP11 -> 0 | AQ2: =IF(AP$2=0,"",AP2/AP$2) | AS2: Faturamento | AT2: =AT11 -> 0 | AU2: =IF(AT$2=0,"",AT2/AT$2) | AW2: Faturamento | AX2: =AX11 -> 0 | AY2: =IF(AX$2=0,"",AX2/AX$2) | BA2: Faturamento | BB2: =BB11 -> 0 | BC2: =IF(BB$2=0,"",BB2/BB$2)
C3: Meta de Faturamento dia = R$2.000,00 | D3: Dispesas | E3: =E10 -> 10921.25 | F3: =IF(E$2=0,"",E3/E$2) -> 1.4085211 | I3: Dispesas | J3: =J10 -> 0 | K3: =IF(J$2=0,"",J3/J$2) | N3: Dispesas | O3: =O10 -> 0 | P3: =IF(O$2=0,"",O3/O$2) | S3: Dispesas | T3: =T10 -> 0 | U3: =IF(T$2=0,"",T3/T$2) | X3: Dispesas | Y3: =Y10 -> 0 | Z3: =IF(Y$2=0,"",Y3/Y$2) | AC3: Dispesas | AD3: =AD10 -> 0 | AE3: =IF(AD$2=0,"",AD3/AD$2) | AG3: Dispesas | AH3: =AH10 -> 0 | AI3: =IF(AH$2=0,"",AH3/AH$2) | AK3: Dispesas | AL3: =AL10 -> 0 | AM3: =IF(AL$2=0,"",AL3/AL$2) | AO3: Dispesas | AP3: =AP10 -> 0 | AQ3: =IF(AP$2=0,"",AP3/AP$2) | AS3: Dispesas | AT3: =AT10 -> 0 | AU3: =IF(AT$2=0,"",AT3/AT$2) | AW3: Dispesas | AX3: =AX10 -> 0 | AY3: =IF(AX$2=0,"",AX3/AX$2) | BA3: Dispesas | BB3: =BB10 -> 0 | BC3: =IF(BB$2=0,"",BB3/BB$2)
C4: Meta de Despesas dia = R$1.700,00 | D4: Lucro | E4: =SUM(E2-E3) -> -3167.55 | F4: =IF(E$2=0,"",E4/E$2) -> -0.40852109 | I4: Lucro | J4: =SUM(J2-J3) -> 0 | K4: =IF(J$2=0,"",J4/J$2) | N4: Lucro | O4: =SUM(O2-O3) -> 0 | P4: =IF(O$2=0,"",O4/O$2) | S4: Lucro | T4: =SUM(T2-T3) -> 0 | U4: =IF(T$2=0,"",T4/T$2) | X4: Lucro | Y4: =SUM(Y2-Y3) -> 0 | Z4: =IF(Y$2=0,"",Y4/Y$2) | AC4: Lucro | AD4: =SUM(AD2-AD3) -> 0 | AE4: =IF(AD$2=0,"",AD4/AD$2) | AG4: Lucro | AH4: =SUM(AH2-AH3) -> 0 | AI4: =IF(AH$2=0,"",AH4/AH$2) | AK4: Lucro | AL4: =SUM(AL2-AL3) -> 0 | AM4: =IF(AL$2=0,"",AL4/AL$2) | AO4: Lucro | AP4: =SUM(AP2-AP3) -> 0 | AQ4: =IF(AP$2=0,"",AP4/AP$2) | AS4: Lucro | AT4: =SUM(AT2-AT3) -> 0 | AU4: =IF(AT$2=0,"",AT4/AT$2) | AW4: Lucro | AX4: =SUM(AX2-AX3) -> 0 | AY4: =IF(AX$2=0,"",AX4/AX$2) | BA4: Lucro | BB4: =SUM(BB2-BB3) -> 0 | BC4: =IF(BB$2=0,"",BB4/BB$2)
C5: FLUXO DE CAIXA | D5: REAL | E5: 0 | F5: =IF(E$2=0,"",E5/E$2) -> 0 | I5: REAL | J5: 0 | K5: =IF(J$2=0,"",J5/J$2) | N5: REAL | O5: 0 | P5: =IF(O$2=0,"",O5/O$2) | S5: REAL | T5: 0 | U5: =IF(T$2=0,"",T5/T$2) | X5: REAL | Y5: 0 | Z5: =IF(Y$2=0,"",Y5/Y$2) | AC5: REAL | AD5: 0 | AE5: =IF(AD$2=0,"",AD5/AD$2) | AG5: REAL | AH5: 0 | AI5: =IF(AH$2=0,"",AH5/AH$2) | AK5: REAL | AL5: 0 | AM5: =IF(AL$2=0,"",AL5/AL$2) | AO5: REAL | AP5: 0 | AQ5: =IF(AP$2=0,"",AP5/AP$2) | AS5: REAL | AT5: 0 | AU5: =IF(AT$2=0,"",AT5/AT$2) | AW5: REAL | AX5: 0 | AY5: =IF(AX$2=0,"",AX5/AX$2) | BA5: REAL | BB5: 0 | BC5: =IF(BB$2=0,"",BB5/BB$2)
C6: 2026 | D6: Diferença | E6: =SUM(E4-E5) -> -3167.55 | I6: Diferença | J6: =SUM(J4-J5) -> 0 | N6: Diferença | O6: =SUM(O4-O5) -> 0 | S6: Diferença | T6: =SUM(T4-T5) -> 0 | X6: Diferença | Y6: =SUM(Y4-Y5) -> 0 | AC6: Diferença | AD6: =SUM(AD4-AD5) -> 0 | AG6: Diferença | AH6: =SUM(AH4-AH5) -> 0 | AK6: Diferença | AL6: =SUM(AL4-AL5) -> 0 | AO6: Diferença | AP6: =SUM(AP4-AP5) -> 0 | AS6: Diferença | AT6: =SUM(AT4-AT5) -> 0 | AW6: Diferença | AX6: =SUM(AX4-AX5) -> 0 | BA6: Diferença | BB6: =SUM(BB4-BB5) -> 0 | BE6: MEDIA | BF6: =SUM(BF11/12) -> 646.14167
C8: =YEAR((TODAY())) -> 2026 | D8: JANEIRO | I8: FEVEREIRO | N8: MARÇO | S8: ABRIL | X8: MAIO | AC8: JUNHO | AG8: JULHO | AK8: AGOSTO | AO8: SETEMBRO | AS8: OUTUBRO | AW8: NOVEMBRO | BA8: DEZEMBRO | BE8: Total Ano | BI8: POR PERÍODO | BK8: 45292
D9: PREVISÃO | E9: REALIZADO | F9: A. V. | G9: A.H. | I9: PREVISÃO | J9: REALIZADO | K9: A. V. | L9: A.H. | N9: PREVISÃO | O9: REALIZADO | P9: A. V. | Q9: A.H. | S9: PREVISÃO | T9: REALIZADO | U9: A. V. | V9: A.H. | X9: PREVISÃO | Y9: REALIZADO | Z9: A. V. | AA9: A.H. | AC9: PREVISÃO | AD9: REALIZADO | AE9: A. V. | AF9: A.H. | AG9: PREVISÃO | AH9: REALIZADO | AI9: A. V. | AJ9: A.H. | AK9: PREVISÃO | AL9: REALIZADO | AM9: A. V. | AN9: A.H. | AO9: PREVISÃO | AP9: REALIZADO | AQ9: A. V. | AR9: A.H. | AS9: PREVISÃO | AT9: REALIZADO | AU9: A. V. | AV9: A.H. | AW9: PREVISÃO | AX9: REALIZADO | AY9: A. V. | AZ9: A.H. | BA9: PREVISÃO | BB9: REALIZADO | BC9: A. V. | BD9: A.H. | BE9: PREVISÃO | BF9: REALIZADO | BG9: A. V. Total | BI9: REALIZADO | BJ9: A. V. | BK9: 45657
C10: RECEITA / FATURAMENTO | D10: DESPESAS | E10: =E321 -> 10921.25 | F10: =F321 -> 1.4085211 | I10: DESPESAS | J10: =J321 -> 0 | K10: =K321 | N10: DESPESAS | O10: =O321 -> 0 | P10: =P321 | S10: DESPESAS | T10: =T321 -> 0 | U10: =U321 | X10: DESPESAS | Y10: =Y321 -> 0 | Z10: =Z321 | AC10: DESPESAS | AD10: =AD321 -> 0 | AE10: =AE321 | AG10: DESPESAS | AH10: =AH321 -> 0 | AI10: =AI321 | AK10: DESPESAS | AL10: =AL321 -> 0 | AM10: =AM321 | AO10: DESPESAS | AP10: =AP321 -> 0 | AQ10: =AQ321 | AS10: DESPESAS | AT10: =AT321 -> 0 | AU10: =AU321 | AW10: DESPESAS | AX10: =AX321 -> 0 | AY10: =AY321 | BA10: DESPESAS | BB10: =BB321 -> 0 | BC10: =BC321 | BK10: =ROUND((BK9-BK8)/30,0.1) -> 12
D11: =D12 -> 3276 | E11: =E12 -> 7753.7 | F11: =IF(E$11=0,"",E11/E$11) -> 1 | G11: =IF(A11=0,"",E11/A11-1) | I11: =I12 -> 0 | J11: =J12 -> 0 | K11: =IF(J$11=0,"",J11/J$11) | L11: =IF(E11=0,"",J11/E11-1) -> -1 | N11: =N12 -> 0 | O11: =O12 -> 0 | P11: =IF(O$11=0,"",O11/O$11) | Q11: =IF(J11=0,"",O11/J11-1) | S11: =S12 -> 0 | T11: =T12 -> 0 | U11: =IF(T$11=0,"",T11/T$11) | V11: =IF(O11=0,"",T11/O11-1) | X11: =X12 -> 0 | Y11: =Y12 -> 0 | Z11: =IF(Y$11=0,"",Y11/Y$11) | AA11: =IF(T11=0,"",Y11/T11-1) | AC11: =AC12 -> 0 | AD11: =AD12 -> 0 | AE11: =IF(AD$11=0,"",AD11/AD$11) | AF11: =IF(Y11=0,"",AD11/Y11-1) | AG11: =AG12 -> 0 | AH11: =AH12 -> 0 | AI11: =IF(AH$11=0,"",AH11/AH$11) | AJ11: =IF(AD11=0,"",AH11/AD11-1) | AK11: =AK12 -> 0 | AL11: =AL12 -> 0 | AM11: =IF(AL$11=0,"",AL11/AL$11) | AN11: =IF(AH11=0,"",AL11/AH11-1) | AO11: =AO12 -> 0 | AP11: =AP12 -> 0 | AQ11: =IF(AP$11=0,"",AP11/AP$11) | AR11: =IF(AL11=0,"",AP11/AL11-1) | AS11: =AS12 -> 0 | AT11: =AT12 -> 0 | AU11: =IF(AT$11=0,"",AT11/AT$11) | AV11: =IF(AP11=0,"",AT11/AP11-1) | AW11: =AW12 -> 0 | AX11: =AX12 -> 0 | AY11: =IF(AX$11=0,"",AX11/AX$11) | AZ11: =IF(AT11=0,"",AX11/AT11-1) | BA11: =BA12 -> 0 | BB11: =BB12 -> 0 | BC11: =IF(BB$11=0,"",BB11/BB$11) | BD11: =IF(AX11=0,"",BB11/AX11-1) | BE11: =SUM(D11,I11,N11,S11,X11,AC11,AG11,AK11,AO11,AS11,AW11,BA11) -> 3276 | BF11: =SUM(E11,J11,O11,T11,Y11,AD11,AH11,AL11,AP11,AT11,AX11,BB11) -> 7753.7 | BG11: =IF(BF$11=0,"",BF11/BF$11) -> 1 | BI11: =BI12 -> 0 | BJ11: =IF(BI$11=0,"",BI11/BI$11) | BK11: meses
C12: 3.1 Receita de Vendas | D12: =SUMIFS('Livro Diario - FC'!$J$11:$J1028,'Livro Diario - FC'!$E$11:$E1028,$C$12,'Livro Diario - FC'!$D$11:$D1028,">=01/01"&$C$7,'Livro Diario - FC'!$D$11:$D1028,"<=31/01"&$C$7)+SUM(D13:D22) -> 3276 | E12: =SUMIFS('Livro Diario - FC'!$L$11:$L1028,'Livro Diario - FC'!$E$11:$E1028,$C$12,'Livro Diario - FC'!$D$11:$D1028,">=01/01"&$C$7,'Livro Diario - FC'!$D$11:$D1028,"<=31/01"&$C$7)+SUM(E13:E22) -> 7753.7 | F12: =IF(E$11=0,"",E12/E$11) -> 1 | G12: =IF(A12=0,"",E12/A12-1) | I12: =SUMIFS('Livro Diario - FC'!$J$11:$J1028,'Livro Diario - FC'!$E$11:$E1028,$C$12,'Livro Diario - FC'!$D$11:$D1028,">=01/02"&$C$7,'Livro Diario - FC'!$D$11:$D1028,"<=29/02"&$C$7)+SUM(I13:I22) -> 0 | J12: =SUMIFS('Livro Diario - FC'!$L$11:$L1028,'Livro Diario - FC'!$E$11:$E1028,$C$12,'Livro Diario - FC'!$D$11:$D1028,">=01/02"&$C$7,'Livro Diario - FC'!$D$11:$D1028,"<=29/02"&$C$7)+SUM(J13:J22) -> 0 | K12: =IF(J$11=0,"",J12/J$11) | L12: =IF(E12=0,"",J12/E12-1) -> -1 | N12: =SUMIFS('Livro Diario - FC'!$J$11:$J1028,'Livro Diario - FC'!$E$11:$E1028,$C$12,'Livro Diario - FC'!$D$11:$D1028,">=01/03"&$C$7,'Livro Diario - FC'!$D$11:$D1028,"<=31/03"&$C$7)+SUM(N13:N22) -> 0 | O12: =SUMIFS('Livro Diario - FC'!$L$11:$L1028,'Livro Diario - FC'!$E$11:$E1028,$C$12,'Livro Diario - FC'!$D$11:$D1028,">=01/03"&$C$7,'Livro Diario - FC'!$D$11:$D1028,"<=31/03"&$C$7)+SUM(O13:O22) -> 0 | P12: =IF(O$11=0,"",O12/O$11) | Q12: =IF(J12=0,"",O12/J12-1) | S12: =SUMIFS('Livro Diario - FC'!$J$11:$J1028,'Livro Diario - FC'!$E$11:$E1028,$C$12,'Livro Diario - FC'!$D$11:$D1028,">=01/04"&$C$7,'Livro Diario - FC'!$D$11:$D1028,"<=30/04"&$C$7)+SUM(S13:S22) -> 0 | T12: =SUMIFS('Livro Diario - FC'!$L$11:$L1028,'Livro Diario - FC'!$E$11:$E1028,$C$12,'Livro Diario - FC'!$D$11:$D1028,">=01/04"&$C$7,'Livro Diario - FC'!$D$11:$D1028,"<=30/04"&$C$7)+SUM(T13:T22) -> 0 | U12: =IF(T$11=0,"",T12/T$11) | V12: =IF(O12=0,"",T12/O12-1) | X12: =SUMIFS('Livro Diario - FC'!$J$11:$J1028,'Livro Diario - FC'!$E$11:$E1028,$C$12,'Livro Diario - FC'!$D$11:$D1028,">=01/05"&$C$7,'Livro Diario - FC'!$D$11:$D1028,"<=31/05"&$C$7)+SUM(X13:X22) -> 0 | Y12: =SUMIFS('Livro Diario - FC'!$L$11:$L1028,'Livro Diario - FC'!$E$11:$E1028,$C$12,'Livro Diario - FC'!$D$11:$D1028,">=01/05"&$C$7,'Livro Diario - FC'!$D$11:$D1028,"<=31/05"&$C$7)+SUM(Y13:Y22) -> 0 | Z12: =IF(Y$11=0,"",Y12/Y$11) | AA12: =IF(T12=0,"",Y12/T12-1) | AC12: =SUMIFS('Livro Diario - FC'!$J$11:$J1028,'Livro Diario - FC'!$E$11:$E1028,$C$12,'Livro Diario - FC'!$D$11:$D1028,">=01/06"&$C$7,'Livro Diario - FC'!$D$11:$D1028,"<=30/06"&$C$7)+SUM(AC13:AC22) -> 0 | AD12: =SUMIFS('Livro Diario - FC'!$L$11:$L1028,'Livro Diario - FC'!$E$11:$E1028,$C$12,'Livro Diario - FC'!$D$11:$D1028,">=01/06"&$C$7,'Livro Diario - FC'!$D$11:$D1028,"<=30/06"&$C$7)+SUM(AD13:AD22) -> 0 | AE12: =IF(AD$11=0,"",AD12/AD$11) | AF12: =IF(Y12=0,"",AD12/Y12-1) | AG12: =SUMIFS('Livro Diario - FC'!$J$11:$J1028,'Livro Diario - FC'!$E$11:$E1028,$C$12,'Livro Diario - FC'!$D$11:$D1028,">=01/07"&$C$7,'Livro Diario - FC'!$D$11:$D1028,"<=31/07"&$C$7)+SUM(AG13:AG22) -> 0 | AH12: =SUMIFS('Livro Diario - FC'!$L$11:$L1028,'Livro Diario - FC'!$E$11:$E1028,$C$12,'Livro Diario - FC'!$D$11:$D1028,">=01/07"&$C$7,'Livro Diario - FC'!$D$11:$D1028,"<=31/07"&$C$7)+SUM(AH13:AH22) -> 0 | AI12: =IF(AH$11=0,"",AH12/AH$11) | AJ12: =IF(AD12=0,"",AH12/AD12-1) | AK12: =SUMIFS('Livro Diario - FC'!$J$11:$J1028,'Livro Diario - FC'!$E$11:$E1028,$C$12,'Livro Diario - FC'!$D$11:$D1028,">=01/08"&$C$7,'Livro Diario - FC'!$D$11:$D1028,"<=31/08"&$C$7)+SUM(AK13:AK22) -> 0 | AL12: =SUMIFS('Livro Diario - FC'!$L$11:$L1028,'Livro Diario - FC'!$E$11:$E1028,$C$12,'Livro Diario - FC'!$D$11:$D1028,">=01/08"&$C$7,'Livro Diario - FC'!$D$11:$D1028,"<=31/08"&$C$7)+SUM(AL13:AL22) -> 0 | AM12: =IF(AL$11=0,"",AL12/AL$11) | AN12: =IF(AH12=0,"",AL12/AH12-1) | AO12: =SUMIFS('Livro Diario - FC'!$J$11:$J1028,'Livro Diario - FC'!$E$11:$E1028,$C$12,'Livro Diario - FC'!$D$11:$D1028,">=01/09"&$C$7,'Livro Diario - FC'!$D$11:$D1028,"<=30/09"&$C$7)+SUM(AO13:AO22) -> 0 | AP12: =SUMIFS('Livro Diario - FC'!$L$11:$L1028,'Livro Diario - FC'!$E$11:$E1028,$C$12,'Livro Diario - FC'!$D$11:$D1028,">=01/09"&$C$7,'Livro Diario - FC'!$D$11:$D1028,"<=30/09"&$C$7)+SUM(AP13:AP22) -> 0 | AQ12: =IF(AP$11=0,"",AP12/AP$11) | AR12: =IF(AL12=0,"",AP12/AL12-1) | AS12: =SUMIFS('Livro Diario - FC'!$J$11:$J1028,'Livro Diario - FC'!$E$11:$E1028,$C$12,'Livro Diario - FC'!$D$11:$D1028,">=01/10"&$C$7,'Livro Diario - FC'!$D$11:$D1028,"<=31/10"&$C$7)+SUM(AS13:AS22) -> 0 | AT12: =SUMIFS('Livro Diario - FC'!$L$11:$L1028,'Livro Diario - FC'!$E$11:$E1028,$C$12,'Livro Diario - FC'!$D$11:$D1028,">=01/10"&$C$7,'Livro Diario - FC'!$D$11:$D1028,"<=31/10"&$C$7)+SUM(AT13:AT22) -> 0 | AU12: =IF(AT$11=0,"",AT12/AT$11) | AV12: =IF(AP12=0,"",AT12/AP12-1) | AW12: =SUMIFS('Livro Diario - FC'!$J$11:$J1028,'Livro Diario - FC'!$E$11:$E1028,$C$12,'Livro Diario - FC'!$D$11:$D1028,">=01/11"&$C$7,'Livro Diario - FC'!$D$11:$D1028,"<=30/11"&$C$7)+SUM(AW13:AW22) -> 0 | AX12: =SUMIFS('Livro Diario - FC'!$L$11:$L1028,'Livro Diario - FC'!$E$11:$E1028,$C$12,'Livro Diario - FC'!$D$11:$D1028,">=01/11"&$C$7,'Livro Diario - FC'!$D$11:$D1028,"<=30/11"&$C$7)+SUM(AX13:AX22) -> 0 | AY12: =IF(AX$11=0,"",AX12/AX$11) | AZ12: =IF(AT12=0,"",AX12/AT12-1) | BA12: =SUMIFS('Livro Diario - FC'!$J$11:$J1028,'Livro Diario - FC'!$E$11:$E1028,$C$12,'Livro Diario - FC'!$D$11:$D1028,">=01/12"&$C$7,'Livro Diario - FC'!$D$11:$D1028,"<=31/12"&$C$7)+SUM(BA13:BA22) -> 0 | BB12: =SUMIFS('Livro Diario - FC'!$L$11:$L1028,'Livro Diario - FC'!$E$11:$E1028,$C$12,'Livro Diario - FC'!$D$11:$D1028,">=01/12"&$C$7,'Livro Diario - FC'!$D$11:$D1028,"<=31/12"&$C$7)+SUM(BB13:BB22) -> 0 | BC12: =IF(BB$11=0,"",BB12/BB$11) | BD12: =IF(AX12=0,"",BB12/AX12-1) | BE12: =SUM(D12,I12,N12,S12,X12,AC12,AG12,AK12,AO12,AS12,AW12,BA12) -> 3276 | BF12: =SUM(E12,J12,O12,T12,Y12,AD12,AH12,AL12,AP12,AT12,AX12,BB12) -> 7753.7 | BG12: =IF(BF$11=0,"",BF12/BF$11) -> 1 | BI12: =SUMIFS('Livro Diario - FC'!$L$11:$L1028,'Livro Diario - FC'!$E$11:$E1028,C13,'Livro Diario - FC'!$D$11:$D1028,">="&$BK$8,'Livro Diario - FC'!$D$11:$D1028,"<="&$BK$9)+SUM(BI13:BI22) -> 0 | BJ12: =IF(BI$11=0,"",BI12/BI$11)
C13: ='Livro Diario - FC'!AE12 -> 3.1.1 Receita com Cash - Diaria | D13: =SUMIFS('Livro Diario - FC'!$J$11:$J1028,'Livro Diario - FC'!$E$11:$E1028,$C$13,'Livro Diario - FC'!$D$11:$D1028,">=01/01"&$C$7,'Livro Diario - FC'!$D$11:$D1028,"<=31/01"&$C$7) -> 3276 | E13: =SUMIFS('Livro Diario - FC'!$L$11:$L1028,'Livro Diario - FC'!$E$11:$E1028,$C$13,'Livro Diario - FC'!$D$11:$D1028,">=01/01"&$C$7,'Livro Diario - FC'!$D$11:$D1028,"<=31/01"&$C$7) -> 7753.7 | F13: =IF(E$11=0,"",E13/E$11) -> 1 | G13: =IF(A13=0,"",E13/A13-1) | I13: =SUMIFS('Livro Diario - FC'!$J$11:$J1028,'Livro Diario - FC'!$E$11:$E1028,$C$13,'Livro Diario - FC'!$D$11:$D1028,">=01/02"&$C$7,'Livro Diario - FC'!$D$11:$D1028,"<=29/02"&$C$7) -> 0 | J13: =SUMIFS('Livro Diario - FC'!$L$11:$L1028,'Livro Diario - FC'!$E$11:$E1028,$C$13,'Livro Diario - FC'!$D$11:$D1028,">=01/02"&$C$7,'Livro Diario - FC'!$D$11:$D1028,"<=29/02"&$C$7) -> 0 | K13: =IF(J$11=0,"",J13/J$11) | L13: =IF(E13=0,"",J13/E13-1) -> -1 | N13: =SUMIFS('Livro Diario - FC'!$J$11:$J1028,'Livro Diario - FC'!$E$11:$E1028,$C$13,'Livro Diario - FC'!$D$11:$D1028,">=01/03"&$C$7,'Livro Diario - FC'!$D$11:$D1028,"<=31/03"&$C$7) -> 0 | O13: =SUMIFS('Livro Diario - FC'!$L$11:$L1028,'Livro Diario - FC'!$E$11:$E1028,$C$13,'Livro Diario - FC'!$D$11:$D1028,">=01/03"&$C$7,'Livro Diario - FC'!$D$11:$D1028,"<=31/03"&$C$7) -> 0 | P13: =IF(O$11=0,"",O13/O$11) | Q13: =IF(J13=0,"",O13/J13-1) | S13: =SUMIFS('Livro Diario - FC'!$J$11:$J1028,'Livro Diario - FC'!$E$11:$E1028,$C$13,'Livro Diario - FC'!$D$11:$D1028,">=01/04"&$C$7,'Livro Diario - FC'!$D$11:$D1028,"<=30/04"&$C$7) -> 0 | T13: =SUMIFS('Livro Diario - FC'!$L$11:$L1028,'Livro Diario - FC'!$E$11:$E1028,$C$13,'Livro Diario - FC'!$D$11:$D1028,">=01/04"&$C$7,'Livro Diario - FC'!$D$11:$D1028,"<=30/04"&$C$7) -> 0 | U13: =IF(T$11=0,"",T13/T$11) | V13: =IF(O13=0,"",T13/O13-1) | X13: =SUMIFS('Livro Diario - FC'!$J$11:$J1028,'Livro Diario - FC'!$E$11:$E1028,$C$13,'Livro Diario - FC'!$D$11:$D1028,">=01/05"&$C$7,'Livro Diario - FC'!$D$11:$D1028,"<=31/05"&$C$7) -> 0 | Y13: =SUMIFS('Livro Diario - FC'!$L$11:$L1028,'Livro Diario - FC'!$E$11:$E1028,$C$13,'Livro Diario - FC'!$D$11:$D1028,">=01/05"&$C$7,'Livro Diario - FC'!$D$11:$D1028,"<=31/05"&$C$7) -> 0 | Z13: =IF(Y$11=0,"",Y13/Y$11) | AA13: =IF(T13=0,"",Y13/T13-1) | AC13: =SUMIFS('Livro Diario - FC'!$J$11:$J1028,'Livro Diario - FC'!$E$11:$E1028,$C$13,'Livro Diario - FC'!$D$11:$D1028,">=01/06"&$C$7,'Livro Diario - FC'!$D$11:$D1028,"<=30/06"&$C$7) -> 0 | AD13: =SUMIFS('Livro Diario - FC'!$L$11:$L1028,'Livro Diario - FC'!$E$11:$E1028,$C$13,'Livro Diario - FC'!$D$11:$D1028,">=01/06"&$C$7,'Livro Diario - FC'!$D$11:$D1028,"<=30/06"&$C$7) -> 0 | AE13: =IF(AD$11=0,"",AD13/AD$11) | AF13: =IF(Y13=0,"",AD13/Y13-1) | AG13: =SUMIFS('Livro Diario - FC'!$J$11:$J1028,'Livro Diario - FC'!$E$11:$E1028,$C$13,'Livro Diario - FC'!$D$11:$D1028,">=01/07"&$C$7,'Livro Diario - FC'!$D$11:$D1028,"<=31/07"&$C$7) -> 0 | AH13: =SUMIFS('Livro Diario - FC'!$L$11:$L1028,'Livro Diario - FC'!$E$11:$E1028,$C$13,'Livro Diario - FC'!$D$11:$D1028,">=01/07"&$C$7,'Livro Diario - FC'!$D$11:$D1028,"<=31/07"&$C$7) -> 0 | AI13: =IF(AH$11=0,"",AH13/AH$11) | AJ13: =IF(AD13=0,"",AH13/AD13-1) | AK13: =SUMIFS('Livro Diario - FC'!$J$11:$J1028,'Livro Diario - FC'!$E$11:$E1028,$C$13,'Livro Diario - FC'!$D$11:$D1028,">=01/08"&$C$7,'Livro Diario - FC'!$D$11:$D1028,"<=31/08"&$C$7) -> 0 | AL13: =SUMIFS('Livro Diario - FC'!$L$11:$L1028,'Livro Diario - FC'!$E$11:$E1028,$C$13,'Livro Diario - FC'!$D$11:$D1028,">=01/08"&$C$7,'Livro Diario - FC'!$D$11:$D1028,"<=31/08"&$C$7) -> 0 | AM13: =IF(AL$11=0,"",AL13/AL$11) | AN13: =IF(AH13=0,"",AL13/AH13-1) | AO13: =SUMIFS('Livro Diario - FC'!$J$11:$J1028,'Livro Diario - FC'!$E$11:$E1028,$C$13,'Livro Diario - FC'!$D$11:$D1028,">=01/09"&$C$7,'Livro Diario - FC'!$D$11:$D1028,"<=30/09"&$C$7) -> 0 | AP13: =SUMIFS('Livro Diario - FC'!$L$11:$L1028,'Livro Diario - FC'!$E$11:$E1028,$C$13,'Livro Diario - FC'!$D$11:$D1028,">=01/09"&$C$7,'Livro Diario - FC'!$D$11:$D1028,"<=30/09"&$C$7) -> 0 | AQ13: =IF(AP$11=0,"",AP13/AP$11) | AR13: =IF(AL13=0,"",AP13/AL13-1) | AS13: =SUMIFS('Livro Diario - FC'!$J$11:$J1028,'Livro Diario - FC'!$E$11:$E1028,$C$13,'Livro Diario - FC'!$D$11:$D1028,">=01/10"&$C$7,'Livro Diario - FC'!$D$11:$D1028,"<=31/10"&$C$7) -> 0 | AT13: =SUMIFS('Livro Diario - FC'!$L$11:$L1028,'Livro Diario - FC'!$E$11:$E1028,$C$13,'Livro Diario - FC'!$D$11:$D1028,">=01/10"&$C$7,'Livro Diario - FC'!$D$11:$D1028,"<=31/10"&$C$7) -> 0 | AU13: =IF(AT$11=0,"",AT13/AT$11) | AV13: =IF(AP13=0,"",AT13/AP13-1) | AW13: =SUMIFS('Livro Diario - FC'!$J$11:$J1028,'Livro Diario - FC'!$E$11:$E1028,$C$13,'Livro Diario - FC'!$D$11:$D1028,">=01/11"&$C$7,'Livro Diario - FC'!$D$11:$D1028,"<=30/11"&$C$7) -> 0 | AX13: =SUMIFS('Livro Diario - FC'!$L$11:$L1028,'Livro Diario - FC'!$E$11:$E1028,$C$13,'Livro Diario - FC'!$D$11:$D1028,">=01/11"&$C$7,'Livro Diario - FC'!$D$11:$D1028,"<=30/11"&$C$7) -> 0 | AY13: =IF(AX$11=0,"",AX13/AX$11) | AZ13: =IF(AT13=0,"",AX13/AT13-1) | BA13: =SUMIFS('Livro Diario - FC'!$J$11:$J1028,'Livro Diario - FC'!$E$11:$E1028,$C$13,'Livro Diario - FC'!$D$11:$D1028,">=01/12"&$C$7,'Livro Diario - FC'!$D$11:$D1028,"<=31/12"&$C$7) -> 0 | BB13: =SUMIFS('Livro Diario - FC'!$L$11:$L1028,'Livro Diario - FC'!$E$11:$E1028,$C$13,'Livro Diario - FC'!$D$11:$D1028,">=01/12"&$C$7,'Livro Diario - FC'!$D$11:$D1028,"<=31/12"&$C$7) -> 0 | BC13: =IF(BB$11=0,"",BB13/BB$11) | BD13: =IF(AX13=0,"",BB13/AX13-1) | BE13: =SUM(D13,I13,N13,S13,X13,AC13,AG13,AK13,AO13,AS13,AW13,BA13) -> 3276 | BF13: =SUM(E13,J13,O13,T13,Y13,AD13,AH13,AL13,AP13,AT13,AX13,BB13) -> 7753.7 | BI13: =SUMIFS('Livro Diario - FC'!$L$11:$L1028,'Livro Diario - FC'!$E$11:$E1028,C13,'Livro Diario - FC'!$D$11:$D1028,">="&$BK$8,'Livro Diario - FC'!$D$11:$D1028,"<="&$BK$9) -> 0
C14: ='Livro Diario - FC'!AE13 -> 3.1.2 Receita com Cartão (Caixa) | D14: =SUMIFS('Livro Diario - FC'!$J$11:$J1028,'Livro Diario - FC'!$E$11:$E1028,$C$14,'Livro Diario - FC'!$D$11:$D1028,">=01/01"&$C$7,'Livro Diario - FC'!$D$11:$D1028,"<=31/01"&$C$7) -> 0 | E14: =SUMIFS('Livro Diario - FC'!$L$11:$L1028,'Livro Diario - FC'!$E$11:$E1028,$C$14,'Livro Diario - FC'!$D$11:$D1028,">=01/01"&$C$7,'Livro Diario - FC'!$D$11:$D1028,"<=31/01"&$C$7) -> 0 | F14: =IF(E$11=0,"",E14/E$11) -> 0 | G14: =IF(A14=0,"",E14/A14-1) | I14: =SUMIFS('Livro Diario - FC'!$J$11:$J1028,'Livro Diario - FC'!$E$11:$E1028,$C$14,'Livro Diario - FC'!$D$11:$D1028,">=01/02"&$C$7,'Livro Diario - FC'!$D$11:$D1028,"<=29/02"&$C$7) -> 0 | J14: =SUMIFS('Livro Diario - FC'!$L$11:$L1028,'Livro Diario - FC'!$E$11:$E1028,$C$14,'Livro Diario - FC'!$D$11:$D1028,">=01/02"&$C$7,'Livro Diario - FC'!$D$11:$D1028,"<=29/02"&$C$7) -> 0 | K14: =IF(J$11=0,"",J14/J$11) | L14: =IF(E14=0,"",J14/E14-1) | N14: =SUMIFS('Livro Diario - FC'!$J$11:$J1028,'Livro Diario - FC'!$E$11:$E1028,$C$14,'Livro Diario - FC'!$D$11:$D1028,">=01/03"&$C$7,'Livro Diario - FC'!$D$11:$D1028,"<=31/03"&$C$7) -> 0 | O14: =SUMIFS('Livro Diario - FC'!$L$11:$L1028,'Livro Diario - FC'!$E$11:$E1028,$C$14,'Livro Diario - FC'!$D$11:$D1028,">=01/03"&$C$7,'Livro Diario - FC'!$D$11:$D1028,"<=31/03"&$C$7) -> 0 | P14: =IF(O$11=0,"",O14/O$11) | Q14: =IF(J14=0,"",O14/J14-1) | S14: =SUMIFS('Livro Diario - FC'!$J$11:$J1028,'Livro Diario - FC'!$E$11:$E1028,$C$14,'Livro Diario - FC'!$D$11:$D1028,">=01/04"&$C$7,'Livro Diario - FC'!$D$11:$D1028,"<=30/04"&$C$7) -> 0 | T14: =SUMIFS('Livro Diario - FC'!$L$11:$L1028,'Livro Diario - FC'!$E$11:$E1028,$C$14,'Livro Diario - FC'!$D$11:$D1028,">=01/04"&$C$7,'Livro Diario - FC'!$D$11:$D1028,"<=30/04"&$C$7) -> 0 | U14: =IF(T$11=0,"",T14/T$11) | V14: =IF(O14=0,"",T14/O14-1) | X14: =SUMIFS('Livro Diario - FC'!$J$11:$J1028,'Livro Diario - FC'!$E$11:$E1028,$C$14,'Livro Diario - FC'!$D$11:$D1028,">=01/05"&$C$7,'Livro Diario - FC'!$D$11:$D1028,"<=31/05"&$C$7) -> 0 | Y14: =SUMIFS('Livro Diario - FC'!$L$11:$L1028,'Livro Diario - FC'!$E$11:$E1028,$C$14,'Livro Diario - FC'!$D$11:$D1028,">=01/05"&$C$7,'Livro Diario - FC'!$D$11:$D1028,"<=31/05"&$C$7) -> 0 | Z14: =IF(Y$11=0,"",Y14/Y$11) | AA14: =IF(T14=0,"",Y14/T14-1) | AC14: =SUMIFS('Livro Diario - FC'!$J$11:$J1028,'Livro Diario - FC'!$E$11:$E1028,$C$14,'Livro Diario - FC'!$D$11:$D1028,">=01/06"&$C$7,'Livro Diario - FC'!$D$11:$D1028,"<=30/06"&$C$7) -> 0 | AD14: =SUMIFS('Livro Diario - FC'!$L$11:$L1028,'Livro Diario - FC'!$E$11:$E1028,$C$14,'Livro Diario - FC'!$D$11:$D1028,">=01/06"&$C$7,'Livro Diario - FC'!$D$11:$D1028,"<=30/06"&$C$7) -> 0 | AE14: =IF(AD$11=0,"",AD14/AD$11) | AF14: =IF(Y14=0,"",AD14/Y14-1) | AG14: =SUMIFS('Livro Diario - FC'!$J$11:$J1028,'Livro Diario - FC'!$E$11:$E1028,$C$14,'Livro Diario - FC'!$D$11:$D1028,">=01/07"&$C$7,'Livro Diario - FC'!$D$11:$D1028,"<=31/07"&$C$7) -> 0 | AH14: =SUMIFS('Livro Diario - FC'!$L$11:$L1028,'Livro Diario - FC'!$E$11:$E1028,$C$14,'Livro Diario - FC'!$D$11:$D1028,">=01/07"&$C$7,'Livro Diario - FC'!$D$11:$D1028,"<=31/07"&$C$7) -> 0 | AI14: =IF(AH$11=0,"",AH14/AH$11) | AJ14: =IF(AD14=0,"",AH14/AD14-1) | AK14: =SUMIFS('Livro Diario - FC'!$J$11:$J1028,'Livro Diario - FC'!$E$11:$E1028,$C$14,'Livro Diario - FC'!$D$11:$D1028,">=01/08"&$C$7,'Livro Diario - FC'!$D$11:$D1028,"<=31/08"&$C$7) -> 0 | AL14: =SUMIFS('Livro Diario - FC'!$L$11:$L1028,'Livro Diario - FC'!$E$11:$E1028,$C$14,'Livro Diario - FC'!$D$11:$D1028,">=01/08"&$C$7,'Livro Diario - FC'!$D$11:$D1028,"<=31/08"&$C$7) -> 0 | AM14: =IF(AL$11=0,"",AL14/AL$11) | AN14: =IF(AH14=0,"",AL14/AH14-1) | AO14: =SUMIFS('Livro Diario - FC'!$J$11:$J1028,'Livro Diario - FC'!$E$11:$E1028,$C$14,'Livro Diario - FC'!$D$11:$D1028,">=01/09"&$C$7,'Livro Diario - FC'!$D$11:$D1028,"<=30/09"&$C$7) -> 0 | AP14: =SUMIFS('Livro Diario - FC'!$L$11:$L1028,'Livro Diario - FC'!$E$11:$E1028,$C$14,'Livro Diario - FC'!$D$11:$D1028,">=01/09"&$C$7,'Livro Diario - FC'!$D$11:$D1028,"<=30/09"&$C$7) -> 0 | AQ14: =IF(AP$11=0,"",AP14/AP$11) | AR14: =IF(AL14=0,"",AP14/AL14-1) | AS14: =SUMIFS('Livro Diario - FC'!$J$11:$J1028,'Livro Diario - FC'!$E$11:$E1028,$C$14,'Livro Diario - FC'!$D$11:$D1028,">=01/10"&$C$7,'Livro Diario - FC'!$D$11:$D1028,"<=31/10"&$C$7) -> 0 | AT14: =SUMIFS('Livro Diario - FC'!$L$11:$L1028,'Livro Diario - FC'!$E$11:$E1028,$C$14,'Livro Diario - FC'!$D$11:$D1028,">=01/10"&$C$7,'Livro Diario - FC'!$D$11:$D1028,"<=31/10"&$C$7) -> 0 | AU14: =IF(AT$11=0,"",AT14/AT$11) | AV14: =IF(AP14=0,"",AT14/AP14-1) | AW14: =SUMIFS('Livro Diario - FC'!$J$11:$J1028,'Livro Diario - FC'!$E$11:$E1028,$C$14,'Livro Diario - FC'!$D$11:$D1028,">=01/11"&$C$7,'Livro Diario - FC'!$D$11:$D1028,"<=30/11"&$C$7) -> 0 | AX14: =SUMIFS('Livro Diario - FC'!$L$11:$L1028,'Livro Diario - FC'!$E$11:$E1028,$C$14,'Livro Diario - FC'!$D$11:$D1028,">=01/11"&$C$7,'Livro Diario - FC'!$D$11:$D1028,"<=30/11"&$C$7) -> 0 | AY14: =IF(AX$11=0,"",AX14/AX$11) | AZ14: =IF(AT14=0,"",AX14/AT14-1) | BA14: =SUMIFS('Livro Diario - FC'!$J$11:$J1028,'Livro Diario - FC'!$E$11:$E1028,$C$14,'Livro Diario - FC'!$D$11:$D1028,">=01/12"&$C$7,'Livro Diario - FC'!$D$11:$D1028,"<=31/12"&$C$7) -> 0 | BB14: =SUMIFS('Livro Diario - FC'!$L$11:$L1028,'Livro Diario - FC'!$E$11:$E1028,$C$14,'Livro Diario - FC'!$D$11:$D1028,">=01/12"&$C$7,'Livro Diario - FC'!$D$11:$D1028,"<=31/12"&$C$7) -> 0 | BC14: =IF(BB$11=0,"",BB14/BB$11) | BD14: =IF(AX14=0,"",BB14/AX14-1) | BE14: =SUM(D14,I14,N14,S14,X14,AC14,AG14,AK14,AO14,AS14,AW14,BA14) -> 0 | BF14: =SUM(E14,J14,O14,T14,Y14,AD14,AH14,AL14,AP14,AT14,AX14,BB14) -> 0 | BI14: =SUMIFS('Livro Diario - FC'!$L$11:$L1028,'Livro Diario - FC'!$E$11:$E1028,C14,'Livro Diario - FC'!$D$11:$D1028,">="&$BK$8,'Livro Diario - FC'!$D$11:$D1028,"<="&$BK$9) -> 0
C15: ='Livro Diario - FC'!AE14 -> 3.1.3 Receita Ifood | D15: =SUMIFS('Livro Diario - FC'!$J$11:$J1028,'Livro Diario - FC'!$E$11:$E1028,$C$15,'Livro Diario - FC'!$D$11:$D1028,">=01/01"&$C$7,'Livro Diario - FC'!$D$11:$D1028,"<=31/01"&$C$7) -> 0 | E15: =SUMIFS('Livro Diario - FC'!$L$11:$L1028,'Livro Diario - FC'!$E$11:$E1028,$C$15,'Livro Diario - FC'!$D$11:$D1028,">=01/01"&$C$7,'Livro Diario - FC'!$D$11:$D1028,"<=31/01"&$C$7) -> 0 | F15: =IF(E$11=0,"",E15/E$11) -> 0 | G15: =IF(A15=0,"",E15/A15-1) | I15: =SUMIFS('Livro Diario - FC'!$J$11:$J1028,'Livro Diario - FC'!$E$11:$E1028,$C$15,'Livro Diario - FC'!$D$11:$D1028,">=01/02"&$C$7,'Livro Diario - FC'!$D$11:$D1028,"<=29/02"&$C$7) -> 0 | J15: =SUMIFS('Livro Diario - FC'!$L$11:$L1028,'Livro Diario - FC'!$E$11:$E1028,$C$15,'Livro Diario - FC'!$D$11:$D1028,">=01/02"&$C$7,'Livro Diario - FC'!$D$11:$D1028,"<=29/02"&$C$7) -> 0 | K15: =IF(J$11=0,"",J15/J$11) | L15: =IF(E15=0,"",J15/E15-1) | N15: =SUMIFS('Livro Diario - FC'!$J$11:$J1028,'Livro Diario - FC'!$E$11:$E1028,$C$15,'Livro Diario - FC'!$D$11:$D1028,">=01/03"&$C$7,'Livro Diario - FC'!$D$11:$D1028,"<=31/03"&$C$7) -> 0 | O15: =SUMIFS('Livro Diario - FC'!$L$11:$L1028,'Livro Diario - FC'!$E$11:$E1028,$C$15,'Livro Diario - FC'!$D$11:$D1028,">=01/03"&$C$7,'Livro Diario - FC'!$D$11:$D1028,"<=31/03"&$C$7) -> 0 | P15: =IF(O$11=0,"",O15/O$11) | Q15: =IF(J15=0,"",O15/J15-1) | S15: =SUMIFS('Livro Diario - FC'!$J$11:$J1028,'Livro Diario - FC'!$E$11:$E1028,$C$15,'Livro Diario - FC'!$D$11:$D1028,">=01/04"&$C$7,'Livro Diario - FC'!$D$11:$D1028,"<=30/04"&$C$7) -> 0 | T15: =SUMIFS('Livro Diario - FC'!$L$11:$L1028,'Livro Diario - FC'!$E$11:$E1028,$C$15,'Livro Diario - FC'!$D$11:$D1028,">=01/04"&$C$7,'Livro Diario - FC'!$D$11:$D1028,"<=30/04"&$C$7) -> 0 | U15: =IF(T$11=0,"",T15/T$11) | V15: =IF(O15=0,"",T15/O15-1) | X15: =SUMIFS('Livro Diario - FC'!$J$11:$J1028,'Livro Diario - FC'!$E$11:$E1028,$C$15,'Livro Diario - FC'!$D$11:$D1028,">=01/05"&$C$7,'Livro Diario - FC'!$D$11:$D1028,"<=31/05"&$C$7) -> 0 | Y15: =SUMIFS('Livro Diario - FC'!$L$11:$L1028,'Livro Diario - FC'!$E$11:$E1028,$C$15,'Livro Diario - FC'!$D$11:$D1028,">=01/05"&$C$7,'Livro Diario - FC'!$D$11:$D1028,"<=31/05"&$C$7) -> 0 | Z15: =IF(Y$11=0,"",Y15/Y$11) | AA15: =IF(T15=0,"",Y15/T15-1) | AC15: =SUMIFS('Livro Diario - FC'!$J$11:$J1028,'Livro Diario - FC'!$E$11:$E1028,$C$15,'Livro Diario - FC'!$D$11:$D1028,">=01/06"&$C$7,'Livro Diario - FC'!$D$11:$D1028,"<=30/06"&$C$7) -> 0 | AD15: =SUMIFS('Livro Diario - FC'!$L$11:$L1028,'Livro Diario - FC'!$E$11:$E1028,$C$15,'Livro Diario - FC'!$D$11:$D1028,">=01/06"&$C$7,'Livro Diario - FC'!$D$11:$D1028,"<=30/06"&$C$7) -> 0 | AE15: =IF(AD$11=0,"",AD15/AD$11) | AF15: =IF(Y15=0,"",AD15/Y15-1) | AG15: =SUMIFS('Livro Diario - FC'!$J$11:$J1028,'Livro Diario - FC'!$E$11:$E1028,$C$15,'Livro Diario - FC'!$D$11:$D1028,">=01/07"&$C$7,'Livro Diario - FC'!$D$11:$D1028,"<=31/07"&$C$7) -> 0 | AH15: =SUMIFS('Livro Diario - FC'!$L$11:$L1028,'Livro Diario - FC'!$E$11:$E1028,$C$15,'Livro Diario - FC'!$D$11:$D1028,">=01/07"&$C$7,'Livro Diario - FC'!$D$11:$D1028,"<=31/07"&$C$7) -> 0 | AI15: =IF(AH$11=0,"",AH15/AH$11) | AJ15: =IF(AD15=0,"",AH15/AD15-1) | AK15: =SUMIFS('Livro Diario - FC'!$J$11:$J1028,'Livro Diario - FC'!$E$11:$E1028,$C$15,'Livro Diario - FC'!$D$11:$D1028,">=01/08"&$C$7,'Livro Diario - FC'!$D$11:$D1028,"<=31/08"&$C$7) -> 0 | AL15: =SUMIFS('Livro Diario - FC'!$L$11:$L1028,'Livro Diario - FC'!$E$11:$E1028,$C$15,'Livro Diario - FC'!$D$11:$D1028,">=01/08"&$C$7,'Livro Diario - FC'!$D$11:$D1028,"<=31/08"&$C$7) -> 0 | AM15: =IF(AL$11=0,"",AL15/AL$11) | AN15: =IF(AH15=0,"",AL15/AH15-1) | AO15: =SUMIFS('Livro Diario - FC'!$J$11:$J1028,'Livro Diario - FC'!$E$11:$E1028,$C$15,'Livro Diario - FC'!$D$11:$D1028,">=01/09"&$C$7,'Livro Diario - FC'!$D$11:$D1028,"<=30/09"&$C$7) -> 0 | AP15: =SUMIFS('Livro Diario - FC'!$L$11:$L1028,'Livro Diario - FC'!$E$11:$E1028,$C$15,'Livro Diario - FC'!$D$11:$D1028,">=01/09"&$C$7,'Livro Diario - FC'!$D$11:$D1028,"<=30/09"&$C$7) -> 0 | AQ15: =IF(AP$11=0,"",AP15/AP$11) | AR15: =IF(AL15=0,"",AP15/AL15-1) | AS15: =SUMIFS('Livro Diario - FC'!$J$11:$J1028,'Livro Diario - FC'!$E$11:$E1028,$C$15,'Livro Diario - FC'!$D$11:$D1028,">=01/10"&$C$7,'Livro Diario - FC'!$D$11:$D1028,"<=31/10"&$C$7) -> 0 | AT15: =SUMIFS('Livro Diario - FC'!$L$11:$L1028,'Livro Diario - FC'!$E$11:$E1028,$C$15,'Livro Diario - FC'!$D$11:$D1028,">=01/10"&$C$7,'Livro Diario - FC'!$D$11:$D1028,"<=31/10"&$C$7) -> 0 | AU15: =IF(AT$11=0,"",AT15/AT$11) | AV15: =IF(AP15=0,"",AT15/AP15-1) | AW15: =SUMIFS('Livro Diario - FC'!$J$11:$J1028,'Livro Diario - FC'!$E$11:$E1028,$C$15,'Livro Diario - FC'!$D$11:$D1028,">=01/11"&$C$7,'Livro Diario - FC'!$D$11:$D1028,"<=30/11"&$C$7) -> 0 | AX15: =SUMIFS('Livro Diario - FC'!$L$11:$L1028,'Livro Diario - FC'!$E$11:$E1028,$C$15,'Livro Diario - FC'!$D$11:$D1028,">=01/11"&$C$7,'Livro Diario - FC'!$D$11:$D1028,"<=30/11"&$C$7) -> 0 | AY15: =IF(AX$11=0,"",AX15/AX$11) | AZ15: =IF(AT15=0,"",AX15/AT15-1) | BA15: =SUMIFS('Livro Diario - FC'!$J$11:$J1028,'Livro Diario - FC'!$E$11:$E1028,$C$15,'Livro Diario - FC'!$D$11:$D1028,">=01/12"&$C$7,'Livro Diario - FC'!$D$11:$D1028,"<=31/12"&$C$7) -> 0 | BB15: =SUMIFS('Livro Diario - FC'!$L$11:$L1028,'Livro Diario - FC'!$E$11:$E1028,$C$15,'Livro Diario - FC'!$D$11:$D1028,">=01/12"&$C$7,'Livro Diario - FC'!$D$11:$D1028,"<=31/12"&$C$7) -> 0 | BC15: =IF(BB$11=0,"",BB15/BB$11) | BD15: =IF(AX15=0,"",BB15/AX15-1) | BE15: =SUM(D15,I15,N15,S15,X15,AC15,AG15,AK15,AO15,AS15,AW15,BA15) -> 0 | BF15: =SUM(E15,J15,O15,T15,Y15,AD15,AH15,AL15,AP15,AT15,AX15,BB15) -> 0 | BI15: =SUMIFS('Livro Diario - FC'!$L$11:$L1028,'Livro Diario - FC'!$E$11:$E1028,C15,'Livro Diario - FC'!$D$11:$D1028,">="&$BK$8,'Livro Diario - FC'!$D$11:$D1028,"<="&$BK$9) -> 0
C16: ='Livro Diario - FC'!AE15 -> 3.1.4 Receita com Cartão - (Infinity Emp) | D16: =SUMIFS('Livro Diario - FC'!$J$11:$J1028,'Livro Diario - FC'!$E$11:$E1028,$C$16,'Livro Diario - FC'!$D$11:$D1028,">=01/01"&$C$7,'Livro Diario - FC'!$D$11:$D1028,"<=31/01"&$C$7) -> 0 | E16: =SUMIFS('Livro Diario - FC'!$L$11:$L1028,'Livro Diario - FC'!$E$11:$E1028,$C$16,'Livro Diario - FC'!$D$11:$D1028,">=01/01"&$C$7,'Livro Diario - FC'!$D$11:$D1028,"<=31/01"&$C$7) -> 0 | F16: =IF(E$11=0,"",E16/E$11) -> 0 | G16: =IF(A16=0,"",E16/A16-1) | I16: =SUMIFS('Livro Diario - FC'!$J$11:$J1028,'Livro Diario - FC'!$E$11:$E1028,$C$16,'Livro Diario - FC'!$D$11:$D1028,">=01/02"&$C$7,'Livro Diario - FC'!$D$11:$D1028,"<=29/02"&$C$7) -> 0 | J16: =SUMIFS('Livro Diario - FC'!$L$11:$L1028,'Livro Diario - FC'!$E$11:$E1028,$C$16,'Livro Diario - FC'!$D$11:$D1028,">=01/02"&$C$7,'Livro Diario - FC'!$D$11:$D1028,"<=29/02"&$C$7) -> 0 | K16: =IF(J$11=0,"",J16/J$11) | L16: =IF(E16=0,"",J16/E16-1) | N16: =SUMIFS('Livro Diario - FC'!$J$11:$J1028,'Livro Diario - FC'!$E$11:$E1028,$C$16,'Livro Diario - FC'!$D$11:$D1028,">=01/03"&$C$7,'Livro Diario - FC'!$D$11:$D1028,"<=31/03"&$C$7) -> 0 | O16: =SUMIFS('Livro Diario - FC'!$L$11:$L1028,'Livro Diario - FC'!$E$11:$E1028,$C$16,'Livro Diario - FC'!$D$11:$D1028,">=01/03"&$C$7,'Livro Diario - FC'!$D$11:$D1028,"<=31/03"&$C$7) -> 0 | P16: =IF(O$11=0,"",O16/O$11) | Q16: =IF(J16=0,"",O16/J16-1) | S16: =SUMIFS('Livro Diario - FC'!$J$11:$J1028,'Livro Diario - FC'!$E$11:$E1028,$C$16,'Livro Diario - FC'!$D$11:$D1028,">=01/04"&$C$7,'Livro Diario - FC'!$D$11:$D1028,"<=30/04"&$C$7) -> 0 | T16: =SUMIFS('Livro Diario - FC'!$L$11:$L1028,'Livro Diario - FC'!$E$11:$E1028,$C$16,'Livro Diario - FC'!$D$11:$D1028,">=01/04"&$C$7,'Livro Diario - FC'!$D$11:$D1028,"<=30/04"&$C$7) -> 0 | U16: =IF(T$11=0,"",T16/T$11) | V16: =IF(O16=0,"",T16/O16-1) | X16: =SUMIFS('Livro Diario - FC'!$J$11:$J1028,'Livro Diario - FC'!$E$11:$E1028,$C$16,'Livro Diario - FC'!$D$11:$D1028,">=01/05"&$C$7,'Livro Diario - FC'!$D$11:$D1028,"<=31/05"&$C$7) -> 0 | Y16: =SUMIFS('Livro Diario - FC'!$L$11:$L1028,'Livro Diario - FC'!$E$11:$E1028,$C$16,'Livro Diario - FC'!$D$11:$D1028,">=01/05"&$C$7,'Livro Diario - FC'!$D$11:$D1028,"<=31/05"&$C$7) -> 0 | Z16: =IF(Y$11=0,"",Y16/Y$11) | AA16: =IF(T16=0,"",Y16/T16-1) | AC16: =SUMIFS('Livro Diario - FC'!$J$11:$J1028,'Livro Diario - FC'!$E$11:$E1028,$C$16,'Livro Diario - FC'!$D$11:$D1028,">=01/06"&$C$7,'Livro Diario - FC'!$D$11:$D1028,"<=30/06"&$C$7) -> 0 | AD16: =SUMIFS('Livro Diario - FC'!$L$11:$L1028,'Livro Diario - FC'!$E$11:$E1028,$C$16,'Livro Diario - FC'!$D$11:$D1028,">=01/06"&$C$7,'Livro Diario - FC'!$D$11:$D1028,"<=30/06"&$C$7) -> 0 | AE16: =IF(AD$11=0,"",AD16/AD$11) | AF16: =IF(Y16=0,"",AD16/Y16-1) | AG16: =SUMIFS('Livro Diario - FC'!$J$11:$J1028,'Livro Diario - FC'!$E$11:$E1028,$C$16,'Livro Diario - FC'!$D$11:$D1028,">=01/07"&$C$7,'Livro Diario - FC'!$D$11:$D1028,"<=31/07"&$C$7) -> 0 | AH16: =SUMIFS('Livro Diario - FC'!$L$11:$L1028,'Livro Diario - FC'!$E$11:$E1028,$C$16,'Livro Diario - FC'!$D$11:$D1028,">=01/07"&$C$7,'Livro Diario - FC'!$D$11:$D1028,"<=31/07"&$C$7) -> 0 | AI16: =IF(AH$11=0,"",AH16/AH$11) | AJ16: =IF(AD16=0,"",AH16/AD16-1) | AK16: =SUMIFS('Livro Diario - FC'!$J$11:$J1028,'Livro Diario - FC'!$E$11:$E1028,$C$16,'Livro Diario - FC'!$D$11:$D1028,">=01/08"&$C$7,'Livro Diario - FC'!$D$11:$D1028,"<=31/08"&$C$7) -> 0 | AL16: =SUMIFS('Livro Diario - FC'!$L$11:$L1028,'Livro Diario - FC'!$E$11:$E1028,$C$16,'Livro Diario - FC'!$D$11:$D1028,">=01/08"&$C$7,'Livro Diario - FC'!$D$11:$D1028,"<=31/08"&$C$7) -> 0 | AM16: =IF(AL$11=0,"",AL16/AL$11) | AN16: =IF(AH16=0,"",AL16/AH16-1) | AO16: =SUMIFS('Livro Diario - FC'!$J$11:$J1028,'Livro Diario - FC'!$E$11:$E1028,$C$16,'Livro Diario - FC'!$D$11:$D1028,">=01/09"&$C$7,'Livro Diario - FC'!$D$11:$D1028,"<=30/09"&$C$7) -> 0 | AP16: =SUMIFS('Livro Diario - FC'!$L$11:$L1028,'Livro Diario - FC'!$E$11:$E1028,$C$16,'Livro Diario - FC'!$D$11:$D1028,">=01/09"&$C$7,'Livro Diario - FC'!$D$11:$D1028,"<=30/09"&$C$7) -> 0 | AQ16: =IF(AP$11=0,"",AP16/AP$11) | AR16: =IF(AL16=0,"",AP16/AL16-1) | AS16: =SUMIFS('Livro Diario - FC'!$J$11:$J1028,'Livro Diario - FC'!$E$11:$E1028,$C$16,'Livro Diario - FC'!$D$11:$D1028,">=01/10"&$C$7,'Livro Diario - FC'!$D$11:$D1028,"<=31/10"&$C$7) -> 0 | AT16: =SUMIFS('Livro Diario - FC'!$L$11:$L1028,'Livro Diario - FC'!$E$11:$E1028,$C$16,'Livro Diario - FC'!$D$11:$D1028,">=01/10"&$C$7,'Livro Diario - FC'!$D$11:$D1028,"<=31/10"&$C$7) -> 0 | AU16: =IF(AT$11=0,"",AT16/AT$11) | AV16: =IF(AP16=0,"",AT16/AP16-1) | AW16: =SUMIFS('Livro Diario - FC'!$J$11:$J1028,'Livro Diario - FC'!$E$11:$E1028,$C$16,'Livro Diario - FC'!$D$11:$D1028,">=01/11"&$C$7,'Livro Diario - FC'!$D$11:$D1028,"<=30/11"&$C$7) -> 0 | AX16: =SUMIFS('Livro Diario - FC'!$L$11:$L1028,'Livro Diario - FC'!$E$11:$E1028,$C$16,'Livro Diario - FC'!$D$11:$D1028,">=01/11"&$C$7,'Livro Diario - FC'!$D$11:$D1028,"<=30/11"&$C$7) -> 0 | AY16: =IF(AX$11=0,"",AX16/AX$11) | AZ16: =IF(AT16=0,"",AX16/AT16-1) | BA16: =SUMIFS('Livro Diario - FC'!$J$11:$J1028,'Livro Diario - FC'!$E$11:$E1028,$C$16,'Livro Diario - FC'!$D$11:$D1028,">=01/12"&$C$7,'Livro Diario - FC'!$D$11:$D1028,"<=31/12"&$C$7) -> 0 | BB16: =SUMIFS('Livro Diario - FC'!$L$11:$L1028,'Livro Diario - FC'!$E$11:$E1028,$C$16,'Livro Diario - FC'!$D$11:$D1028,">=01/12"&$C$7,'Livro Diario - FC'!$D$11:$D1028,"<=31/12"&$C$7) -> 0 | BC16: =IF(BB$11=0,"",BB16/BB$11) | BD16: =IF(AX16=0,"",BB16/AX16-1) | BE16: =SUM(D16,I16,N16,S16,X16,AC16,AG16,AK16,AO16,AS16,AW16,BA16) -> 0 | BF16: =SUM(E16,J16,O16,T16,Y16,AD16,AH16,AL16,AP16,AT16,AX16,BB16) -> 0 | BI16: =SUMIFS('Livro Diario - FC'!$L$11:$L1028,'Livro Diario - FC'!$E$11:$E1028,C16,'Livro Diario - FC'!$D$11:$D1028,">="&$BK$8,'Livro Diario - FC'!$D$11:$D1028,"<="&$BK$9) -> 0
C17: ='Livro Diario - FC'!AE16 -> 3.1.5 Receita com Cartão - (Infinity Sil) | D17: =SUMIFS('Livro Diario - FC'!$J$11:$J1028,'Livro Diario - FC'!$E$11:$E1028,$C$17,'Livro Diario - FC'!$D$11:$D1028,">=01/01"&$C$7,'Livro Diario - FC'!$D$11:$D1028,"<=31/01"&$C$7) -> 0 | E17: =SUMIFS('Livro Diario - FC'!$L$11:$L1028,'Livro Diario - FC'!$E$11:$E1028,$C$17,'Livro Diario - FC'!$D$11:$D1028,">=01/01"&$C$7,'Livro Diario - FC'!$D$11:$D1028,"<=31/01"&$C$7) -> 0 | F17: =IF(E$11=0,"",E17/E$11) -> 0 | I17: =SUMIFS('Livro Diario - FC'!$J$11:$J1028,'Livro Diario - FC'!$E$11:$E1028,$C$17,'Livro Diario - FC'!$D$11:$D1028,">=01/02"&$C$7,'Livro Diario - FC'!$D$11:$D1028,"<=29/02"&$C$7) -> 0 | J17: =SUMIFS('Livro Diario - FC'!$L$11:$L1028,'Livro Diario - FC'!$E$11:$E1028,$C$17,'Livro Diario - FC'!$D$11:$D1028,">=01/02"&$C$7,'Livro Diario - FC'!$D$11:$D1028,"<=29/02"&$C$7) -> 0 | K17: =IF(J$11=0,"",J17/J$11) | N17: =SUMIFS('Livro Diario - FC'!$J$11:$J1028,'Livro Diario - FC'!$E$11:$E1028,$C$17,'Livro Diario - FC'!$D$11:$D1028,">=01/03"&$C$7,'Livro Diario - FC'!$D$11:$D1028,"<=31/03"&$C$7) -> 0 | O17: =SUMIFS('Livro Diario - FC'!$L$11:$L1028,'Livro Diario - FC'!$E$11:$E1028,$C$17,'Livro Diario - FC'!$D$11:$D1028,">=01/03"&$C$7,'Livro Diario - FC'!$D$11:$D1028,"<=31/03"&$C$7) -> 0 | P17: =IF(O$11=0,"",O17/O$11) | S17: =SUMIFS('Livro Diario - FC'!$J$11:$J1028,'Livro Diario - FC'!$E$11:$E1028,$C$17,'Livro Diario - FC'!$D$11:$D1028,">=01/04"&$C$7,'Livro Diario - FC'!$D$11:$D1028,"<=30/04"&$C$7) -> 0 | T17: =SUMIFS('Livro Diario - FC'!$L$11:$L1028,'Livro Diario - FC'!$E$11:$E1028,$C$17,'Livro Diario - FC'!$D$11:$D1028,">=01/04"&$C$7,'Livro Diario - FC'!$D$11:$D1028,"<=30/04"&$C$7) -> 0 | U17: =IF(T$11=0,"",T17/T$11) | X17: =SUMIFS('Livro Diario - FC'!$J$11:$J1028,'Livro Diario - FC'!$E$11:$E1028,$C$17,'Livro Diario - FC'!$D$11:$D1028,">=01/05"&$C$7,'Livro Diario - FC'!$D$11:$D1028,"<=31/05"&$C$7) -> 0 | Y17: =SUMIFS('Livro Diario - FC'!$L$11:$L1028,'Livro Diario - FC'!$E$11:$E1028,$C$17,'Livro Diario - FC'!$D$11:$D1028,">=01/05"&$C$7,'Livro Diario - FC'!$D$11:$D1028,"<=31/05"&$C$7) -> 0 | Z17: =IF(Y$11=0,"",Y17/Y$11) | AC17: =SUMIFS('Livro Diario - FC'!$J$11:$J1028,'Livro Diario - FC'!$E$11:$E1028,$C$17,'Livro Diario - FC'!$D$11:$D1028,">=01/06"&$C$7,'Livro Diario - FC'!$D$11:$D1028,"<=30/06"&$C$7) -> 0 | AD17: =SUMIFS('Livro Diario - FC'!$L$11:$L1028,'Livro Diario - FC'!$E$11:$E1028,$C$17,'Livro Diario - FC'!$D$11:$D1028,">=01/06"&$C$7,'Livro Diario - FC'!$D$11:$D1028,"<=30/06"&$C$7) -> 0 | AE17: =IF(AD$11=0,"",AD17/AD$11) | AG17: =SUMIFS('Livro Diario - FC'!$J$11:$J1028,'Livro Diario - FC'!$E$11:$E1028,$C$17,'Livro Diario - FC'!$D$11:$D1028,">=01/07"&$C$7,'Livro Diario - FC'!$D$11:$D1028,"<=31/07"&$C$7) -> 0 | AH17: =SUMIFS('Livro Diario - FC'!$L$11:$L1028,'Livro Diario - FC'!$E$11:$E1028,$C$17,'Livro Diario - FC'!$D$11:$D1028,">=01/07"&$C$7,'Livro Diario - FC'!$D$11:$D1028,"<=31/07"&$C$7) -> 0 | AI17: =IF(AH$11=0,"",AH17/AH$11) | AK17: =SUMIFS('Livro Diario - FC'!$J$11:$J1028,'Livro Diario - FC'!$E$11:$E1028,$C$17,'Livro Diario - FC'!$D$11:$D1028,">=01/08"&$C$7,'Livro Diario - FC'!$D$11:$D1028,"<=31/08"&$C$7) -> 0 | AL17: =SUMIFS('Livro Diario - FC'!$L$11:$L1028,'Livro Diario - FC'!$E$11:$E1028,$C$17,'Livro Diario - FC'!$D$11:$D1028,">=01/08"&$C$7,'Livro Diario - FC'!$D$11:$D1028,"<=31/08"&$C$7) -> 0 | AM17: =IF(AL$11=0,"",AL17/AL$11) | AO17: =SUMIFS('Livro Diario - FC'!$J$11:$J1028,'Livro Diario - FC'!$E$11:$E1028,$C$17,'Livro Diario - FC'!$D$11:$D1028,">=01/09"&$C$7,'Livro Diario - FC'!$D$11:$D1028,"<=30/09"&$C$7) -> 0 | AP17: =SUMIFS('Livro Diario - FC'!$L$11:$L1028,'Livro Diario - FC'!$E$11:$E1028,$C$17,'Livro Diario - FC'!$D$11:$D1028,">=01/09"&$C$7,'Livro Diario - FC'!$D$11:$D1028,"<=30/09"&$C$7) -> 0 | AQ17: =IF(AP$11=0,"",AP17/AP$11) | AS17: =SUMIFS('Livro Diario - FC'!$J$11:$J1028,'Livro Diario - FC'!$E$11:$E1028,$C$17,'Livro Diario - FC'!$D$11:$D1028,">=01/10"&$C$7,'Livro Diario - FC'!$D$11:$D1028,"<=31/10"&$C$7) -> 0 | AT17: =SUMIFS('Livro Diario - FC'!$L$11:$L1028,'Livro Diario - FC'!$E$11:$E1028,$C$17,'Livro Diario - FC'!$D$11:$D1028,">=01/10"&$C$7,'Livro Diario - FC'!$D$11:$D1028,"<=31/10"&$C$7) -> 0 | AU17: =IF(AT$11=0,"",AT17/AT$11) | AW17: =SUMIFS('Livro Diario - FC'!$J$11:$J1028,'Livro Diario - FC'!$E$11:$E1028,$C$17,'Livro Diario - FC'!$D$11:$D1028,">=01/11"&$C$7,'Livro Diario - FC'!$D$11:$D1028,"<=30/11"&$C$7) -> 0 | AX17: =SUMIFS('Livro Diario - FC'!$L$11:$L1028,'Livro Diario - FC'!$E$11:$E1028,$C$17,'Livro Diario - FC'!$D$11:$D1028,">=01/11"&$C$7,'Livro Diario - FC'!$D$11:$D1028,"<=30/11"&$C$7) -> 0 | AY17: =IF(AX$11=0,"",AX17/AX$11) | BA17: =SUMIFS('Livro Diario - FC'!$J$11:$J1028,'Livro Diario - FC'!$E$11:$E1028,$C$17,'Livro Diario - FC'!$D$11:$D1028,">=01/12"&$C$7,'Livro Diario - FC'!$D$11:$D1028,"<=31/12"&$C$7) -> 0 | BB17: =SUMIFS('Livro Diario - FC'!$L$11:$L1028,'Livro Diario - FC'!$E$11:$E1028,$C$17,'Livro Diario - FC'!$D$11:$D1028,">=01/12"&$C$7,'Livro Diario - FC'!$D$11:$D1028,"<=31/12"&$C$7) -> 0 | BC17: =IF(BB$11=0,"",BB17/BB$11) | BE17: =SUM(D17,I17,N17,S17,X17,AC17,AG17,AK17,AO17,AS17,AW17,BA17) -> 0 | BF17: =SUM(E17,J17,O17,T17,Y17,AD17,AH17,AL17,AP17,AT17,AX17,BB17) -> 0 | BI17: =SUMIFS('Livro Diario - FC'!$L$11:$L1028,'Livro Diario - FC'!$E$11:$E1028,C17,'Livro Diario - FC'!$D$11:$D1028,">="&$BK$8,'Livro Diario - FC'!$D$11:$D1028,"<="&$BK$9) -> 0
C18: ='Livro Diario - FC'!AE17 -> 3.1.6 - | D18: =SUMIFS('Livro Diario - FC'!$J$11:$J1028,'Livro Diario - FC'!$E$11:$E1028,$C$18,'Livro Diario - FC'!$D$11:$D1028,">=01/01"&$C$7,'Livro Diario - FC'!$D$11:$D1028,"<=31/01"&$C$7) -> 0 | E18: =SUMIFS('Livro Diario - FC'!$L$11:$L1028,'Livro Diario - FC'!$E$11:$E1028,$C$18,'Livro Diario - FC'!$D$11:$D1028,">=01/01"&$C$7,'Livro Diario - FC'!$D$11:$D1028,"<=31/01"&$C$7) -> 0 | F18: =IF(E$11=0,"",E18/E$11) -> 0 | I18: =SUMIFS('Livro Diario - FC'!$J$11:$J1028,'Livro Diario - FC'!$E$11:$E1028,$C$18,'Livro Diario - FC'!$D$11:$D1028,">=01/02"&$C$7,'Livro Diario - FC'!$D$11:$D1028,"<=29/02"&$C$7) -> 0 | J18: =SUMIFS('Livro Diario - FC'!$L$11:$L1028,'Livro Diario - FC'!$E$11:$E1028,$C$18,'Livro Diario - FC'!$D$11:$D1028,">=01/02"&$C$7,'Livro Diario - FC'!$D$11:$D1028,"<=29/02"&$C$7) -> 0 | K18: =IF(J$11=0,"",J18/J$11) | N18: =SUMIFS('Livro Diario - FC'!$J$11:$J1028,'Livro Diario - FC'!$E$11:$E1028,$C$18,'Livro Diario - FC'!$D$11:$D1028,">=01/03"&$C$7,'Livro Diario - FC'!$D$11:$D1028,"<=31/03"&$C$7) -> 0 | O18: =SUMIFS('Livro Diario - FC'!$L$11:$L1028,'Livro Diario - FC'!$E$11:$E1028,$C$18,'Livro Diario - FC'!$D$11:$D1028,">=01/03"&$C$7,'Livro Diario - FC'!$D$11:$D1028,"<=31/03"&$C$7) -> 0 | P18: =IF(O$11=0,"",O18/O$11) | S18: =SUMIFS('Livro Diario - FC'!$J$11:$J1028,'Livro Diario - FC'!$E$11:$E1028,$C$18,'Livro Diario - FC'!$D$11:$D1028,">=01/04"&$C$7,'Livro Diario - FC'!$D$11:$D1028,"<=30/04"&$C$7) -> 0 | T18: =SUMIFS('Livro Diario - FC'!$L$11:$L1028,'Livro Diario - FC'!$E$11:$E1028,$C$18,'Livro Diario - FC'!$D$11:$D1028,">=01/04"&$C$7,'Livro Diario - FC'!$D$11:$D1028,"<=30/04"&$C$7) -> 0 | U18: =IF(T$11=0,"",T18/T$11) | X18: =SUMIFS('Livro Diario - FC'!$J$11:$J1028,'Livro Diario - FC'!$E$11:$E1028,$C$18,'Livro Diario - FC'!$D$11:$D1028,">=01/05"&$C$7,'Livro Diario - FC'!$D$11:$D1028,"<=31/05"&$C$7) -> 0 | Y18: =SUMIFS('Livro Diario - FC'!$L$11:$L1028,'Livro Diario - FC'!$E$11:$E1028,$C$18,'Livro Diario - FC'!$D$11:$D1028,">=01/05"&$C$7,'Livro Diario - FC'!$D$11:$D1028,"<=31/05"&$C$7) -> 0 | Z18: =IF(Y$11=0,"",Y18/Y$11) | AC18: =SUMIFS('Livro Diario - FC'!$J$11:$J1028,'Livro Diario - FC'!$E$11:$E1028,$C$18,'Livro Diario - FC'!$D$11:$D1028,">=01/06"&$C$7,'Livro Diario - FC'!$D$11:$D1028,"<=30/06"&$C$7) -> 0 | AD18: =SUMIFS('Livro Diario - FC'!$L$11:$L1028,'Livro Diario - FC'!$E$11:$E1028,$C$18,'Livro Diario - FC'!$D$11:$D1028,">=01/06"&$C$7,'Livro Diario - FC'!$D$11:$D1028,"<=30/06"&$C$7) -> 0 | AE18: =IF(AD$11=0,"",AD18/AD$11) | AG18: =SUMIFS('Livro Diario - FC'!$J$11:$J1028,'Livro Diario - FC'!$E$11:$E1028,$C$18,'Livro Diario - FC'!$D$11:$D1028,">=01/07"&$C$7,'Livro Diario - FC'!$D$11:$D1028,"<=31/07"&$C$7) -> 0 | AH18: =SUMIFS('Livro Diario - FC'!$L$11:$L1028,'Livro Diario - FC'!$E$11:$E1028,$C$18,'Livro Diario - FC'!$D$11:$D1028,">=01/07"&$C$7,'Livro Diario - FC'!$D$11:$D1028,"<=31/07"&$C$7) -> 0 | AI18: =IF(AH$11=0,"",AH18/AH$11) | AK18: =SUMIFS('Livro Diario - FC'!$J$11:$J1028,'Livro Diario - FC'!$E$11:$E1028,$C$18,'Livro Diario - FC'!$D$11:$D1028,">=01/08"&$C$7,'Livro Diario - FC'!$D$11:$D1028,"<=31/08"&$C$7) -> 0 | AL18: =SUMIFS('Livro Diario - FC'!$L$11:$L1028,'Livro Diario - FC'!$E$11:$E1028,$C$18,'Livro Diario - FC'!$D$11:$D1028,">=01/08"&$C$7,'Livro Diario - FC'!$D$11:$D1028,"<=31/08"&$C$7) -> 0 | AM18: =IF(AL$11=0,"",AL18/AL$11) | AO18: =SUMIFS('Livro Diario - FC'!$J$11:$J1028,'Livro Diario - FC'!$E$11:$E1028,$C$18,'Livro Diario - FC'!$D$11:$D1028,">=01/09"&$C$7,'Livro Diario - FC'!$D$11:$D1028,"<=30/09"&$C$7) -> 0 | AP18: =SUMIFS('Livro Diario - FC'!$L$11:$L1028,'Livro Diario - FC'!$E$11:$E1028,$C$18,'Livro Diario - FC'!$D$11:$D1028,">=01/09"&$C$7,'Livro Diario - FC'!$D$11:$D1028,"<=30/09"&$C$7) -> 0 | AQ18: =IF(AP$11=0,"",AP18/AP$11) | AS18: =SUMIFS('Livro Diario - FC'!$J$11:$J1028,'Livro Diario - FC'!$E$11:$E1028,$C$18,'Livro Diario - FC'!$D$11:$D1028,">=01/10"&$C$7,'Livro Diario - FC'!$D$11:$D1028,"<=31/10"&$C$7) -> 0 | AT18: =SUMIFS('Livro Diario - FC'!$L$11:$L1028,'Livro Diario - FC'!$E$11:$E1028,$C$18,'Livro Diario - FC'!$D$11:$D1028,">=01/10"&$C$7,'Livro Diario - FC'!$D$11:$D1028,"<=31/10"&$C$7) -> 0 | AU18: =IF(AT$11=0,"",AT18/AT$11) | AW18: =SUMIFS('Livro Diario - FC'!$J$11:$J1028,'Livro Diario - FC'!$E$11:$E1028,$C$18,'Livro Diario - FC'!$D$11:$D1028,">=01/11"&$C$7,'Livro Diario - FC'!$D$11:$D1028,"<=30/11"&$C$7) -> 0 | AX18: =SUMIFS('Livro Diario - FC'!$L$11:$L1028,'Livro Diario - FC'!$E$11:$E1028,$C$18,'Livro Diario - FC'!$D$11:$D1028,">=01/11"&$C$7,'Livro Diario - FC'!$D$11:$D1028,"<=30/11"&$C$7) -> 0 | AY18: =IF(AX$11=0,"",AX18/AX$11) | BA18: =SUMIFS('Livro Diario - FC'!$J$11:$J1028,'Livro Diario - FC'!$E$11:$E1028,$C$18,'Livro Diario - FC'!$D$11:$D1028,">=01/12"&$C$7,'Livro Diario - FC'!$D$11:$D1028,"<=31/12"&$C$7) -> 0 | BB18: =SUMIFS('Livro Diario - FC'!$L$11:$L1028,'Livro Diario - FC'!$E$11:$E1028,$C$18,'Livro Diario - FC'!$D$11:$D1028,">=01/12"&$C$7,'Livro Diario - FC'!$D$11:$D1028,"<=31/12"&$C$7) -> 0 | BC18: =IF(BB$11=0,"",BB18/BB$11) | BE18: =SUM(D18,I18,N18,S18,X18,AC18,AG18,AK18,AO18,AS18,AW18,BA18) -> 0 | BF18: =SUM(E18,J18,O18,T18,Y18,AD18,AH18,AL18,AP18,AT18,AX18,BB18) -> 0 | BI18: =SUMIFS('Livro Diario - FC'!$L$11:$L1028,'Livro Diario - FC'!$E$11:$E1028,C18,'Livro Diario - FC'!$D$11:$D1028,">="&$BK$8,'Livro Diario - FC'!$D$11:$D1028,"<="&$BK$9) -> 0
